{
 "cells": [
  {
   "cell_type": "code",
   "execution_count": 1,
   "metadata": {},
   "outputs": [],
   "source": [
    "import tensorflow as tf\n",
    "import matplotlib.pyplot as plt\n",
    "from tensorflow.keras import layers,models\n",
    "from tensorflow import keras\n",
    "import numpy as np"
   ]
  },
  {
   "cell_type": "code",
   "execution_count": 2,
   "metadata": {},
   "outputs": [],
   "source": [
    "#(X_train, y_train) , (X_test, y_test) = keras.datasets.mnist.load_data()\n",
    "#(train_images, train_labels), (test_images, test_labels) = datasets.cifar10.load_data()\n",
    "(X_train, y_train) , (X_test, y_test) = keras.datasets.mnist.load_data()\n",
    "X_train = X_train / 255\n",
    "X_test = X_test / 255\n",
    "X_train = X_train.reshape(-1,28,28,1)\n",
    "X_test = X_test.reshape(-1,28,28,1)\n",
    "x_val = X_train[:5000,:,:,:]\n",
    "y_val = y_train[:5000]\n",
    "x_train = X_train[5000:,:,:,:]\n",
    "y_train = y_train[5000:]"
   ]
  },
  {
   "cell_type": "code",
   "execution_count": 3,
   "metadata": {},
   "outputs": [
    {
     "name": "stderr",
     "output_type": "stream",
     "text": [
      "ERROR:root:Internal Python error in the inspect module.\n",
      "Below is the traceback from this internal error.\n",
      "\n",
      "ERROR:root:Internal Python error in the inspect module.\n",
      "Below is the traceback from this internal error.\n",
      "\n",
      "ERROR:root:Internal Python error in the inspect module.\n",
      "Below is the traceback from this internal error.\n",
      "\n"
     ]
    },
    {
     "name": "stdout",
     "output_type": "stream",
     "text": [
      "Traceback (most recent call last):\n",
      "  File \"c:\\Users\\fabri\\anaconda3\\envs\\tensorflow-directml\\lib\\site-packages\\IPython\\core\\interactiveshell.py\", line 3343, in run_code\n",
      "    exec(code_obj, self.user_global_ns, self.user_ns)\n",
      "  File \"<ipython-input-3-f870b85dfa5f>\", line 13, in <module>\n",
      "    plt.xlabel(class_names[y_train[i][0]])\n",
      "IndexError: invalid index to scalar variable.\n",
      "\n",
      "During handling of the above exception, another exception occurred:\n",
      "\n",
      "Traceback (most recent call last):\n",
      "  File \"c:\\Users\\fabri\\anaconda3\\envs\\tensorflow-directml\\lib\\site-packages\\IPython\\core\\interactiveshell.py\", line 2044, in showtraceback\n",
      "    stb = value._render_traceback_()\n",
      "AttributeError: 'IndexError' object has no attribute '_render_traceback_'\n",
      "\n",
      "During handling of the above exception, another exception occurred:\n",
      "\n",
      "Traceback (most recent call last):\n",
      "  File \"c:\\Users\\fabri\\anaconda3\\envs\\tensorflow-directml\\lib\\site-packages\\IPython\\core\\ultratb.py\", line 1169, in get_records\n",
      "    return _fixed_getinnerframes(etb, number_of_lines_of_context, tb_offset)\n",
      "  File \"c:\\Users\\fabri\\anaconda3\\envs\\tensorflow-directml\\lib\\site-packages\\IPython\\core\\ultratb.py\", line 316, in wrapped\n",
      "    return f(*args, **kwargs)\n",
      "  File \"c:\\Users\\fabri\\anaconda3\\envs\\tensorflow-directml\\lib\\site-packages\\IPython\\core\\ultratb.py\", line 350, in _fixed_getinnerframes\n",
      "    records = fix_frame_records_filenames(inspect.getinnerframes(etb, context))\n",
      "  File \"c:\\Users\\fabri\\anaconda3\\envs\\tensorflow-directml\\lib\\inspect.py\", line 1490, in getinnerframes\n",
      "    frameinfo = (tb.tb_frame,) + getframeinfo(tb, context)\n",
      "  File \"c:\\Users\\fabri\\anaconda3\\envs\\tensorflow-directml\\lib\\inspect.py\", line 1448, in getframeinfo\n",
      "    filename = getsourcefile(frame) or getfile(frame)\n",
      "  File \"c:\\Users\\fabri\\anaconda3\\envs\\tensorflow-directml\\lib\\inspect.py\", line 696, in getsourcefile\n",
      "    if getattr(getmodule(object, filename), '__loader__', None) is not None:\n",
      "  File \"c:\\Users\\fabri\\anaconda3\\envs\\tensorflow-directml\\lib\\inspect.py\", line 733, in getmodule\n",
      "    if ismodule(module) and hasattr(module, '__file__'):\n",
      "  File \"c:\\Users\\fabri\\anaconda3\\envs\\tensorflow-directml\\lib\\site-packages\\tensorflow\\__init__.py\", line 50, in __getattr__\n",
      "    module = self._load()\n",
      "  File \"c:\\Users\\fabri\\anaconda3\\envs\\tensorflow-directml\\lib\\site-packages\\tensorflow\\__init__.py\", line 44, in _load\n",
      "    module = _importlib.import_module(self.__name__)\n",
      "  File \"c:\\Users\\fabri\\anaconda3\\envs\\tensorflow-directml\\lib\\importlib\\__init__.py\", line 126, in import_module\n",
      "    return _bootstrap._gcd_import(name[level:], package, level)\n",
      "  File \"<frozen importlib._bootstrap>\", line 994, in _gcd_import\n",
      "  File \"<frozen importlib._bootstrap>\", line 971, in _find_and_load\n",
      "  File \"<frozen importlib._bootstrap>\", line 955, in _find_and_load_unlocked\n",
      "  File \"<frozen importlib._bootstrap>\", line 665, in _load_unlocked\n",
      "  File \"<frozen importlib._bootstrap_external>\", line 678, in exec_module\n",
      "  File \"<frozen importlib._bootstrap>\", line 219, in _call_with_frames_removed\n",
      "  File \"c:\\Users\\fabri\\anaconda3\\envs\\tensorflow-directml\\lib\\site-packages\\tensorflow_core\\contrib\\__init__.py\", line 39, in <module>\n",
      "    from tensorflow.contrib import compiler\n",
      "  File \"c:\\Users\\fabri\\anaconda3\\envs\\tensorflow-directml\\lib\\site-packages\\tensorflow_core\\contrib\\compiler\\__init__.py\", line 21, in <module>\n",
      "    from tensorflow.contrib.compiler import jit\n",
      "  File \"c:\\Users\\fabri\\anaconda3\\envs\\tensorflow-directml\\lib\\site-packages\\tensorflow_core\\contrib\\compiler\\__init__.py\", line 22, in <module>\n",
      "    from tensorflow.contrib.compiler import xla\n",
      "  File \"c:\\Users\\fabri\\anaconda3\\envs\\tensorflow-directml\\lib\\site-packages\\tensorflow_core\\contrib\\compiler\\xla.py\", line 22, in <module>\n",
      "    from tensorflow.python.estimator import model_fn as model_fn_lib\n",
      "  File \"c:\\Users\\fabri\\anaconda3\\envs\\tensorflow-directml\\lib\\site-packages\\tensorflow_core\\python\\estimator\\model_fn.py\", line 26, in <module>\n",
      "    from tensorflow_estimator.python.estimator import model_fn\n",
      "  File \"c:\\Users\\fabri\\anaconda3\\envs\\tensorflow-directml\\lib\\site-packages\\tensorflow_estimator\\__init__.py\", line 10, in <module>\n",
      "    from tensorflow_estimator._api.v1 import estimator\n",
      "  File \"c:\\Users\\fabri\\anaconda3\\envs\\tensorflow-directml\\lib\\site-packages\\tensorflow_estimator\\_api\\v1\\estimator\\__init__.py\", line 10, in <module>\n",
      "    from tensorflow_estimator._api.v1.estimator import experimental\n",
      "  File \"c:\\Users\\fabri\\anaconda3\\envs\\tensorflow-directml\\lib\\site-packages\\tensorflow_estimator\\_api\\v1\\estimator\\experimental\\__init__.py\", line 10, in <module>\n",
      "    from tensorflow_estimator.python.estimator.canned.dnn import dnn_logit_fn_builder\n",
      "  File \"c:\\Users\\fabri\\anaconda3\\envs\\tensorflow-directml\\lib\\site-packages\\tensorflow_estimator\\python\\estimator\\canned\\dnn.py\", line 27, in <module>\n",
      "    from tensorflow_estimator.python.estimator import estimator\n",
      "  File \"c:\\Users\\fabri\\anaconda3\\envs\\tensorflow-directml\\lib\\site-packages\\tensorflow_estimator\\python\\estimator\\estimator.py\", line 36, in <module>\n",
      "    from tensorflow.python.profiler import trace\n",
      "ImportError: cannot import name 'trace'\n",
      "Traceback (most recent call last):\n",
      "  File \"c:\\Users\\fabri\\anaconda3\\envs\\tensorflow-directml\\lib\\site-packages\\IPython\\core\\interactiveshell.py\", line 3343, in run_code\n",
      "    exec(code_obj, self.user_global_ns, self.user_ns)\n",
      "  File \"<ipython-input-3-f870b85dfa5f>\", line 13, in <module>\n",
      "    plt.xlabel(class_names[y_train[i][0]])\n",
      "IndexError: invalid index to scalar variable.\n",
      "\n",
      "During handling of the above exception, another exception occurred:\n",
      "\n",
      "Traceback (most recent call last):\n",
      "  File \"c:\\Users\\fabri\\anaconda3\\envs\\tensorflow-directml\\lib\\site-packages\\IPython\\core\\interactiveshell.py\", line 2044, in showtraceback\n",
      "    stb = value._render_traceback_()\n",
      "AttributeError: 'IndexError' object has no attribute '_render_traceback_'\n",
      "\n",
      "During handling of the above exception, another exception occurred:\n",
      "\n",
      "Traceback (most recent call last):\n",
      "  File \"c:\\Users\\fabri\\anaconda3\\envs\\tensorflow-directml\\lib\\site-packages\\IPython\\core\\interactiveshell.py\", line 3263, in run_ast_nodes\n",
      "    if (await self.run_code(code, result,  async_=asy)):\n",
      "  File \"c:\\Users\\fabri\\anaconda3\\envs\\tensorflow-directml\\lib\\site-packages\\IPython\\core\\interactiveshell.py\", line 3360, in run_code\n",
      "    self.showtraceback(running_compiled_code=True)\n",
      "  File \"c:\\Users\\fabri\\anaconda3\\envs\\tensorflow-directml\\lib\\site-packages\\IPython\\core\\interactiveshell.py\", line 2047, in showtraceback\n",
      "    value, tb, tb_offset=tb_offset)\n",
      "  File \"c:\\Users\\fabri\\anaconda3\\envs\\tensorflow-directml\\lib\\site-packages\\IPython\\core\\ultratb.py\", line 1436, in structured_traceback\n",
      "    self, etype, value, tb, tb_offset, number_of_lines_of_context)\n",
      "  File \"c:\\Users\\fabri\\anaconda3\\envs\\tensorflow-directml\\lib\\site-packages\\IPython\\core\\ultratb.py\", line 1336, in structured_traceback\n",
      "    self, etype, value, tb, tb_offset, number_of_lines_of_context\n",
      "  File \"c:\\Users\\fabri\\anaconda3\\envs\\tensorflow-directml\\lib\\site-packages\\IPython\\core\\ultratb.py\", line 1193, in structured_traceback\n",
      "    tb_offset)\n",
      "  File \"c:\\Users\\fabri\\anaconda3\\envs\\tensorflow-directml\\lib\\site-packages\\IPython\\core\\ultratb.py\", line 1150, in format_exception_as_a_whole\n",
      "    last_unique, recursion_repeat = find_recursion(orig_etype, evalue, records)\n",
      "  File \"c:\\Users\\fabri\\anaconda3\\envs\\tensorflow-directml\\lib\\site-packages\\IPython\\core\\ultratb.py\", line 451, in find_recursion\n",
      "    return len(records), 0\n",
      "TypeError: object of type 'NoneType' has no len()\n",
      "\n",
      "During handling of the above exception, another exception occurred:\n",
      "\n",
      "Traceback (most recent call last):\n",
      "  File \"c:\\Users\\fabri\\anaconda3\\envs\\tensorflow-directml\\lib\\site-packages\\IPython\\core\\interactiveshell.py\", line 2044, in showtraceback\n",
      "    stb = value._render_traceback_()\n",
      "AttributeError: 'TypeError' object has no attribute '_render_traceback_'\n",
      "\n",
      "During handling of the above exception, another exception occurred:\n",
      "\n",
      "Traceback (most recent call last):\n",
      "  File \"c:\\Users\\fabri\\anaconda3\\envs\\tensorflow-directml\\lib\\site-packages\\IPython\\core\\ultratb.py\", line 1169, in get_records\n",
      "    return _fixed_getinnerframes(etb, number_of_lines_of_context, tb_offset)\n",
      "  File \"c:\\Users\\fabri\\anaconda3\\envs\\tensorflow-directml\\lib\\site-packages\\IPython\\core\\ultratb.py\", line 316, in wrapped\n",
      "    return f(*args, **kwargs)\n",
      "  File \"c:\\Users\\fabri\\anaconda3\\envs\\tensorflow-directml\\lib\\site-packages\\IPython\\core\\ultratb.py\", line 350, in _fixed_getinnerframes\n",
      "    records = fix_frame_records_filenames(inspect.getinnerframes(etb, context))\n",
      "  File \"c:\\Users\\fabri\\anaconda3\\envs\\tensorflow-directml\\lib\\inspect.py\", line 1490, in getinnerframes\n",
      "    frameinfo = (tb.tb_frame,) + getframeinfo(tb, context)\n",
      "  File \"c:\\Users\\fabri\\anaconda3\\envs\\tensorflow-directml\\lib\\inspect.py\", line 1448, in getframeinfo\n",
      "    filename = getsourcefile(frame) or getfile(frame)\n",
      "  File \"c:\\Users\\fabri\\anaconda3\\envs\\tensorflow-directml\\lib\\inspect.py\", line 696, in getsourcefile\n",
      "    if getattr(getmodule(object, filename), '__loader__', None) is not None:\n",
      "  File \"c:\\Users\\fabri\\anaconda3\\envs\\tensorflow-directml\\lib\\inspect.py\", line 733, in getmodule\n",
      "    if ismodule(module) and hasattr(module, '__file__'):\n",
      "  File \"c:\\Users\\fabri\\anaconda3\\envs\\tensorflow-directml\\lib\\site-packages\\tensorflow\\__init__.py\", line 50, in __getattr__\n",
      "    module = self._load()\n",
      "  File \"c:\\Users\\fabri\\anaconda3\\envs\\tensorflow-directml\\lib\\site-packages\\tensorflow\\__init__.py\", line 44, in _load\n",
      "    module = _importlib.import_module(self.__name__)\n",
      "  File \"c:\\Users\\fabri\\anaconda3\\envs\\tensorflow-directml\\lib\\importlib\\__init__.py\", line 126, in import_module\n",
      "    return _bootstrap._gcd_import(name[level:], package, level)\n",
      "  File \"<frozen importlib._bootstrap>\", line 994, in _gcd_import\n",
      "  File \"<frozen importlib._bootstrap>\", line 971, in _find_and_load\n",
      "  File \"<frozen importlib._bootstrap>\", line 953, in _find_and_load_unlocked\n",
      "ModuleNotFoundError: No module named 'tensorflow_core.estimator'\n",
      "Traceback (most recent call last):\n",
      "  File \"c:\\Users\\fabri\\anaconda3\\envs\\tensorflow-directml\\lib\\site-packages\\IPython\\core\\interactiveshell.py\", line 3343, in run_code\n",
      "    exec(code_obj, self.user_global_ns, self.user_ns)\n",
      "  File \"<ipython-input-3-f870b85dfa5f>\", line 13, in <module>\n",
      "    plt.xlabel(class_names[y_train[i][0]])\n",
      "IndexError: invalid index to scalar variable.\n",
      "\n",
      "During handling of the above exception, another exception occurred:\n",
      "\n",
      "Traceback (most recent call last):\n",
      "  File \"c:\\Users\\fabri\\anaconda3\\envs\\tensorflow-directml\\lib\\site-packages\\IPython\\core\\interactiveshell.py\", line 2044, in showtraceback\n",
      "    stb = value._render_traceback_()\n",
      "AttributeError: 'IndexError' object has no attribute '_render_traceback_'\n",
      "\n",
      "During handling of the above exception, another exception occurred:\n",
      "\n",
      "Traceback (most recent call last):\n",
      "  File \"c:\\Users\\fabri\\anaconda3\\envs\\tensorflow-directml\\lib\\site-packages\\IPython\\core\\interactiveshell.py\", line 3263, in run_ast_nodes\n",
      "    if (await self.run_code(code, result,  async_=asy)):\n",
      "  File \"c:\\Users\\fabri\\anaconda3\\envs\\tensorflow-directml\\lib\\site-packages\\IPython\\core\\interactiveshell.py\", line 3360, in run_code\n",
      "    self.showtraceback(running_compiled_code=True)\n",
      "  File \"c:\\Users\\fabri\\anaconda3\\envs\\tensorflow-directml\\lib\\site-packages\\IPython\\core\\interactiveshell.py\", line 2047, in showtraceback\n",
      "    value, tb, tb_offset=tb_offset)\n",
      "  File \"c:\\Users\\fabri\\anaconda3\\envs\\tensorflow-directml\\lib\\site-packages\\IPython\\core\\ultratb.py\", line 1436, in structured_traceback\n",
      "    self, etype, value, tb, tb_offset, number_of_lines_of_context)\n",
      "  File \"c:\\Users\\fabri\\anaconda3\\envs\\tensorflow-directml\\lib\\site-packages\\IPython\\core\\ultratb.py\", line 1336, in structured_traceback\n",
      "    self, etype, value, tb, tb_offset, number_of_lines_of_context\n",
      "  File \"c:\\Users\\fabri\\anaconda3\\envs\\tensorflow-directml\\lib\\site-packages\\IPython\\core\\ultratb.py\", line 1193, in structured_traceback\n",
      "    tb_offset)\n",
      "  File \"c:\\Users\\fabri\\anaconda3\\envs\\tensorflow-directml\\lib\\site-packages\\IPython\\core\\ultratb.py\", line 1150, in format_exception_as_a_whole\n",
      "    last_unique, recursion_repeat = find_recursion(orig_etype, evalue, records)\n",
      "  File \"c:\\Users\\fabri\\anaconda3\\envs\\tensorflow-directml\\lib\\site-packages\\IPython\\core\\ultratb.py\", line 451, in find_recursion\n",
      "    return len(records), 0\n",
      "TypeError: object of type 'NoneType' has no len()\n",
      "\n",
      "During handling of the above exception, another exception occurred:\n",
      "\n",
      "Traceback (most recent call last):\n",
      "  File \"c:\\Users\\fabri\\anaconda3\\envs\\tensorflow-directml\\lib\\site-packages\\IPython\\core\\interactiveshell.py\", line 2044, in showtraceback\n",
      "    stb = value._render_traceback_()\n",
      "AttributeError: 'TypeError' object has no attribute '_render_traceback_'\n",
      "\n",
      "During handling of the above exception, another exception occurred:\n",
      "\n",
      "Traceback (most recent call last):\n",
      "  File \"c:\\Users\\fabri\\anaconda3\\envs\\tensorflow-directml\\lib\\site-packages\\IPython\\core\\interactiveshell.py\", line 2895, in _run_cell\n",
      "    return runner(coro)\n",
      "  File \"c:\\Users\\fabri\\anaconda3\\envs\\tensorflow-directml\\lib\\site-packages\\IPython\\core\\async_helpers.py\", line 68, in _pseudo_sync_runner\n",
      "    coro.send(None)\n",
      "  File \"c:\\Users\\fabri\\anaconda3\\envs\\tensorflow-directml\\lib\\site-packages\\IPython\\core\\interactiveshell.py\", line 3072, in run_cell_async\n",
      "    interactivity=interactivity, compiler=compiler, result=result)\n",
      "  File \"c:\\Users\\fabri\\anaconda3\\envs\\tensorflow-directml\\lib\\site-packages\\IPython\\core\\interactiveshell.py\", line 3282, in run_ast_nodes\n",
      "    self.showtraceback()\n",
      "  File \"c:\\Users\\fabri\\anaconda3\\envs\\tensorflow-directml\\lib\\site-packages\\IPython\\core\\interactiveshell.py\", line 2047, in showtraceback\n",
      "    value, tb, tb_offset=tb_offset)\n",
      "  File \"c:\\Users\\fabri\\anaconda3\\envs\\tensorflow-directml\\lib\\site-packages\\IPython\\core\\ultratb.py\", line 1436, in structured_traceback\n",
      "    self, etype, value, tb, tb_offset, number_of_lines_of_context)\n",
      "  File \"c:\\Users\\fabri\\anaconda3\\envs\\tensorflow-directml\\lib\\site-packages\\IPython\\core\\ultratb.py\", line 1336, in structured_traceback\n",
      "    self, etype, value, tb, tb_offset, number_of_lines_of_context\n",
      "  File \"c:\\Users\\fabri\\anaconda3\\envs\\tensorflow-directml\\lib\\site-packages\\IPython\\core\\ultratb.py\", line 1211, in structured_traceback\n",
      "    chained_exceptions_tb_offset)\n",
      "  File \"c:\\Users\\fabri\\anaconda3\\envs\\tensorflow-directml\\lib\\site-packages\\IPython\\core\\ultratb.py\", line 1150, in format_exception_as_a_whole\n",
      "    last_unique, recursion_repeat = find_recursion(orig_etype, evalue, records)\n",
      "  File \"c:\\Users\\fabri\\anaconda3\\envs\\tensorflow-directml\\lib\\site-packages\\IPython\\core\\ultratb.py\", line 451, in find_recursion\n",
      "    return len(records), 0\n",
      "TypeError: object of type 'NoneType' has no len()\n",
      "\n",
      "During handling of the above exception, another exception occurred:\n",
      "\n",
      "Traceback (most recent call last):\n",
      "  File \"c:\\Users\\fabri\\anaconda3\\envs\\tensorflow-directml\\lib\\site-packages\\IPython\\core\\interactiveshell.py\", line 2044, in showtraceback\n",
      "    stb = value._render_traceback_()\n",
      "AttributeError: 'TypeError' object has no attribute '_render_traceback_'\n",
      "\n",
      "During handling of the above exception, another exception occurred:\n",
      "\n",
      "Traceback (most recent call last):\n",
      "  File \"c:\\Users\\fabri\\anaconda3\\envs\\tensorflow-directml\\lib\\site-packages\\IPython\\core\\ultratb.py\", line 1169, in get_records\n",
      "    return _fixed_getinnerframes(etb, number_of_lines_of_context, tb_offset)\n",
      "  File \"c:\\Users\\fabri\\anaconda3\\envs\\tensorflow-directml\\lib\\site-packages\\IPython\\core\\ultratb.py\", line 316, in wrapped\n",
      "    return f(*args, **kwargs)\n",
      "  File \"c:\\Users\\fabri\\anaconda3\\envs\\tensorflow-directml\\lib\\site-packages\\IPython\\core\\ultratb.py\", line 350, in _fixed_getinnerframes\n",
      "    records = fix_frame_records_filenames(inspect.getinnerframes(etb, context))\n",
      "  File \"c:\\Users\\fabri\\anaconda3\\envs\\tensorflow-directml\\lib\\inspect.py\", line 1490, in getinnerframes\n",
      "    frameinfo = (tb.tb_frame,) + getframeinfo(tb, context)\n",
      "  File \"c:\\Users\\fabri\\anaconda3\\envs\\tensorflow-directml\\lib\\inspect.py\", line 1448, in getframeinfo\n",
      "    filename = getsourcefile(frame) or getfile(frame)\n",
      "  File \"c:\\Users\\fabri\\anaconda3\\envs\\tensorflow-directml\\lib\\inspect.py\", line 696, in getsourcefile\n",
      "    if getattr(getmodule(object, filename), '__loader__', None) is not None:\n",
      "  File \"c:\\Users\\fabri\\anaconda3\\envs\\tensorflow-directml\\lib\\inspect.py\", line 733, in getmodule\n",
      "    if ismodule(module) and hasattr(module, '__file__'):\n",
      "  File \"c:\\Users\\fabri\\anaconda3\\envs\\tensorflow-directml\\lib\\site-packages\\tensorflow\\__init__.py\", line 50, in __getattr__\n",
      "    module = self._load()\n",
      "  File \"c:\\Users\\fabri\\anaconda3\\envs\\tensorflow-directml\\lib\\site-packages\\tensorflow\\__init__.py\", line 44, in _load\n",
      "    module = _importlib.import_module(self.__name__)\n",
      "  File \"c:\\Users\\fabri\\anaconda3\\envs\\tensorflow-directml\\lib\\importlib\\__init__.py\", line 126, in import_module\n",
      "    return _bootstrap._gcd_import(name[level:], package, level)\n",
      "  File \"<frozen importlib._bootstrap>\", line 994, in _gcd_import\n",
      "  File \"<frozen importlib._bootstrap>\", line 971, in _find_and_load\n",
      "  File \"<frozen importlib._bootstrap>\", line 953, in _find_and_load_unlocked\n",
      "ModuleNotFoundError: No module named 'tensorflow_core.estimator'\n"
     ]
    },
    {
     "data": {
      "image/png": "iVBORw0KGgoAAAANSUhEUgAAARgAAAEYCAYAAACHjumMAAAAOXRFWHRTb2Z0d2FyZQBNYXRwbG90bGliIHZlcnNpb24zLjMuNCwgaHR0cHM6Ly9tYXRwbG90bGliLm9yZy8QVMy6AAAACXBIWXMAAAsTAAALEwEAmpwYAAAIMElEQVR4nO3dX6zWdQHH8d/jOfwJBPWEmm6GBBhMSSoWMBm0sciLLmrNmPMmWhdp6CraLNf6N2q2NTci8sLN0C3LdLa86M8Fa8wtOGU2W7WkCdQUOglnQCEKPufXRSu6oH2/h3M+53AeXq/b89n3+W1ub39s3z1Pp23bBiDhksl+AKB3CQwQIzBAjMAAMQIDxAgMENM/mvH0zox2ZjM79SzAFPRac7I53b7eOdffRhWYmc3sZmVn/fg8FdATBttd//dv/okExAgMECMwQIzAADECA8QIDBAjMECMwAAxAgPECAwQIzBAjMAAMQIDxAgMECMwQIzAADECA8QIDBAjMECMwAAxAgPECAwQIzBAjMAAMQIDxAgMECMwQIzAADECA8QIDBAjMECMwAAxAgPECAwQIzBAjMAAMQIDxAgMECMwQIzAADECA8QIDBAjMECMwAAx/ZP9AEysTn/5P3nflfMm4EnOeuGz11fturNGipv5C/9e3My6q1P1eX97YHpx89yKx6vOOtI9WdysfGJLcbPoM3urPu9C4Q0GiBEYIEZggBiBAWIEBogRGCBGYIAYgQFiXLQL6Vu6uGrXzphW3Bxad3lxc2pV+SJX0zTNwGXl3TM3110euxD99NU5xc03vn1r1VmDyx4rbg6cOVV11v1D7yturn2mrTprKvEGA8QIDBAjMECMwAAxAgPECAwQIzBAjMAAMQIDxLjJex66731XcfPAzh1VZ90wrfy1jPzbmbZb3Hxx+0eLm/6TdTdmVz+xubiZ8/IbVWfNOFK+8Tvr2cGqs6YSbzBAjMAAMQIDxAgMECMwQIzAADECA8QIDBDjot15mPHCoeLmN69dV3XWDdOGxvo4k2LL4VVVu/3/LP/O9c6FT1addXykfEHu6m/9suqsidZ7X4ZZxxsMECMwQIzAADECA8QIDBAjMECMwAAxAgPECAwQ02nb+juGczsD7crO+uDj9I7hTaurdiduLf8Yfd/vLi1unr9re9Xn1dh65B3Fza/XlW/oNk3TdI8dL27a1TdXnXXwnvJmwe3PV53F+BlsdzUn2uHOuf7mDQaIERggRmCAGIEBYgQGiBEYIEZggBiBAWJctJtkffPeXNx0jw4XNwceK1+Oa5qm+cPah4ub93z97uLmqh0X5ldTMvFctAMmhcAAMQIDxAgMECMwQIzAADECA8QIDBDjt6knWffI0XE558yJ6eNyTtM0zY13/LG4eeXBvrrDRrpjfBqmMm8wQIzAADECA8QIDBAjMECMwAAxAgPECAwQIzBAjJu8PWLpvfuqdpuWlb/y9LvzdxU36277ZNXnzXl8b9WO3uQNBogRGCBGYIAYgQFiBAaIERggRmCAGIEBYly06xHdY8erdkfvXFrc/PXpU8XN57Y+WvV5n//Ih4qb9reXVZ113df2lEej+K118rzBADECA8QIDBAjMECMwAAxAgPECAwQIzBATKcdxcWkuZ2BdmWn/I1oTG3DH1td3HzvS9+sOmtB/8yxPs5/3fjo5uJm8UOHi5s39h8ch6fhPwbbXc2Jdrhzrr95gwFiBAaIERggRmCAGIEBYgQGiBEYIEZggBiBAWLc5OW8tLcsr9rNvf+l4ub7b/v5GJ/mrCW/+Hhx8/av1H29aPfP+8f6OBcFN3mBSSEwQIzAADECA8QIDBAjMECMwAAxAgPEuGhHVN/VVxU3hzYuqjpr8N5txc0lFf/PvOPAhqrPO77maNXuYueiHTApBAaIERggRmCAGIEBYgQGiBEYIEZggBiBAWLc5GXK+OFLe4qbWZ3pxc2r7emqz/vA3Z8qf96PBqvO6mVu8gKTQmCAGIEBYgQGiBEYIEZggBiBAWIEBojpn+wHYGoaWbO8avfibTOLm5uWH6w6q+YSXY3tw++s+7wfPzsun3cx8wYDxAgMECMwQIzAADECA8QIDBAjMECMwAAxLtpdZDorbipu9t1TvtD20C2PVH3e2pl13x43Xl5vzxQ3e4cX1B02cniMT4M3GCBGYIAYgQFiBAaIERggRmCAGIEBYgQGiBEYIMZN3imgf8H84ubFTddWnfXljT8obj586ZGqsybafUMripvd21YVN1c8Uv6Na8aHNxggRmCAGIEBYgQGiBEYIEZggBiBAWIEBohx0S6k//q3Vu2Ov/ua4mbjV39W3Hzi8qeqPm+ibTlcvvi25zvlC3RN0zQDO39V3Fwx4hLdhcQbDBAjMECMwAAxAgPECAwQIzBAjMAAMQIDxAgMEOMm7//ov+YtVbvhh2cXN3cu2F111u1zhqp2E2nzy2uKm+ceXF511rwnf1/cDPzD7dte5Q0GiBEYIEZggBiBAWIEBogRGCBGYIAYgQFieuKi3en3l79y8fSnh4ub+xb9pOrzNrzpZNVuIg11T1Xt1j69pbhZ8oU/FTcDx+oux41UrehV3mCAGIEBYgQGiBEYIEZggBiBAWIEBogRGCCmJy7aHfxguZP7lj0xAU9y1o5jC6t223ZvKG463U5xs2TrgarPWzw0WNx0q06CMm8wQIzAADECA8QIDBAjMECMwAAxAgPECAwQIzBATKdt2+rx3M5Au7KzPvg4wFQz2O5qTrTD57xu7g0GiBEYIEZggBiBAWIEBogRGCBGYIAYgQFiBAaIERggRmCAGIEBYgQGiBEYIEZggBiBAWIEBogRGCBGYIAYgQFiBAaIERggRmCAGIEBYgQGiBEYIEZggJhR/TZ1p9N5pWmav+QeB5iC5rdte+W5/jCqwACMhn8iATECA8QIDBAjMECMwAAxAgPECAwQIzBAjMAAMf8CjjREZ6JhRFAAAAAASUVORK5CYII=",
      "text/plain": [
       "<Figure size 2016x2016 with 1 Axes>"
      ]
     },
     "metadata": {},
     "output_type": "display_data"
    },
    {
     "ename": "",
     "evalue": "",
     "output_type": "error",
     "traceback": [
      "\u001b[1;31mCanceled future for execute_request message before replies were done"
     ]
    }
   ],
   "source": [
    "class_names = ['airplane', 'automobile', 'bird', 'cat', 'deer',\n",
    "               'dog', 'frog', 'horse', 'ship', 'truck']\n",
    "\n",
    "plt.figure(figsize=(28,28))\n",
    "for i in range(5):\n",
    "    plt.subplot(5,5,i+1)\n",
    "    plt.xticks([])\n",
    "    plt.yticks([])\n",
    "    plt.grid(False)\n",
    "    plt.imshow(X_train[i])\n",
    "    # The CIFAR labels happen to be arrays, \n",
    "    # which is why you need the extra index\n",
    "    plt.xlabel(class_names[y_train[i][0]])\n",
    "plt.show()"
   ]
  },
  {
   "cell_type": "code",
   "execution_count": null,
   "metadata": {},
   "outputs": [],
   "source": [
    "model = models.Sequential([\n",
    "    layers.Conv2D(filters=25, kernel_size=(3, 3), activation='relu', input_shape=(28,28,1)),\n",
    "    layers.MaxPooling2D((2, 2)),\n",
    "    \n",
    "    layers.Conv2D(filters=64, kernel_size=(3, 3), activation='relu'),\n",
    "    layers.MaxPooling2D((2, 2)),\n",
    "\n",
    "    layers.Conv2D(filters=64, kernel_size=(3, 3), activation='relu'),\n",
    "    layers.MaxPooling2D((2, 2)),\n",
    "    \n",
    "    layers.Flatten(),\n",
    "    layers.Dense(64, activation='relu'),\n",
    "    layers.Dense(10, activation='softmax')\n",
    "])"
   ]
  },
  {
   "cell_type": "code",
   "execution_count": 1,
   "metadata": {},
   "outputs": [
    {
     "ename": "NameError",
     "evalue": "name 'model' is not defined",
     "output_type": "error",
     "traceback": [
      "\u001b[1;31m---------------------------------------------------------------------------\u001b[0m",
      "\u001b[1;31mNameError\u001b[0m                                 Traceback (most recent call last)",
      "\u001b[1;32m<ipython-input-1-5f15418b3570>\u001b[0m in \u001b[0;36m<module>\u001b[1;34m\u001b[0m\n\u001b[1;32m----> 1\u001b[1;33m \u001b[0mmodel\u001b[0m\u001b[1;33m.\u001b[0m\u001b[0msummary\u001b[0m\u001b[1;33m(\u001b[0m\u001b[1;33m)\u001b[0m\u001b[1;33m\u001b[0m\u001b[1;33m\u001b[0m\u001b[0m\n\u001b[0m",
      "\u001b[1;31mNameError\u001b[0m: name 'model' is not defined"
     ]
    }
   ],
   "source": [
    "model.summary()"
   ]
  },
  {
   "cell_type": "code",
   "execution_count": null,
   "metadata": {},
   "outputs": [],
   "source": [
    "#model.compile(optimizer='adam', loss='sparse_categorical_crossentropy', metrics=['accuracy'])\n",
    "model.compile(optimizer='adam',\n",
    "              loss=tf.keras.losses.SparseCategoricalCrossentropy(from_logits=True),\n",
    "              metrics=['accuracy'])\n",
    "history = model.fit(X_train, y_train, epochs=2)\n"
   ]
  },
  {
   "cell_type": "code",
   "execution_count": null,
   "metadata": {},
   "outputs": [],
   "source": [
    "plt.plot(history.history['accuracy'], label='accuracy')\n",
    "plt.plot(history.history['val_accuracy'], label = 'val_accuracy')\n",
    "plt.xlabel('Epoch')\n",
    "plt.ylabel('Accuracy')\n",
    "plt.ylim([0.5, 1])\n",
    "plt.legend(loc='lower right')\n",
    "\n",
    "test_loss, test_acc = model.evaluate(test_images,  test_labels, verbose=2)"
   ]
  },
  {
   "cell_type": "code",
   "execution_count": null,
   "metadata": {},
   "outputs": [],
   "source": [
    "acc = history.History['acc']\n",
    "val_acc = history.History['val_acc']\n",
    "loss = history.History['loss']\n",
    "val_loss = history.History['loss']\n",
    "epochs = range(1,len(acc)+1)\n",
    "\n",
    "\n",
    "plt.plot(epochs, acc, label='Training accuracy', marker='x')\n",
    "plt.plot(epochs, val_acc, label='Validation accuracy' ,marker='o')\n",
    "plt.title('Training and validation')\n",
    "plt.lengend()\n",
    "plt.figure()\n",
    "\n",
    "plt.plot(epochs, loss,label='Training loss',marker='x')\n",
    "plt.plot(epochs, val_loss, label='Validation loss' ,marker='o')\n",
    "plt.title('Training and validation loss')\n",
    "plt.legend()\n",
    "\n",
    "plt.show()\n"
   ]
  },
  {
   "cell_type": "code",
   "execution_count": null,
   "metadata": {},
   "outputs": [],
   "source": [
    "model.evaluate(X_test, y_test)"
   ]
  },
  {
   "cell_type": "code",
   "execution_count": null,
   "metadata": {},
   "outputs": [],
   "source": [
    "y_predicted_by_model = model.predict(X_test)\n",
    "y_predicted_by_model[0]"
   ]
  },
  {
   "cell_type": "code",
   "execution_count": null,
   "metadata": {},
   "outputs": [],
   "source": [
    "np.argmax(y_predicted_by_model[0])"
   ]
  },
  {
   "cell_type": "code",
   "execution_count": null,
   "metadata": {},
   "outputs": [],
   "source": [
    "y_predicted_labels = [np.argmax(i) for i in y_predicted_by_model]"
   ]
  },
  {
   "cell_type": "code",
   "execution_count": null,
   "metadata": {},
   "outputs": [],
   "source": [
    "y_predicted_labels[:5]"
   ]
  }
 ],
 "metadata": {
  "kernelspec": {
   "display_name": "Python 3.6.13 ('tensorflow-directml')",
   "language": "python",
   "name": "python3"
  },
  "language_info": {
   "codemirror_mode": {
    "name": "ipython",
    "version": 3
   },
   "file_extension": ".py",
   "mimetype": "text/x-python",
   "name": "python",
   "nbconvert_exporter": "python",
   "pygments_lexer": "ipython3",
   "version": "3.6.13"
  },
  "orig_nbformat": 4,
  "vscode": {
   "interpreter": {
    "hash": "068d618c100932174e8099a6d5c2d1b31961f2d9a41e8860777d6ea05b0369d7"
   }
  }
 },
 "nbformat": 4,
 "nbformat_minor": 2
}
